# 非同期コードのテスト

Javascript は言語の特性的に非同期的に作動するコードが多いです。

Jest では非同期関数をテストすることができます。

## Callback パターン

`index.js`

```javascript
const fn = {
  // 3秒後にcallbackを実行するgetName
  getName: (callback) => {
    const name = "terry";
    setTimeout(() => callback(name), 3000);
  },
};

// Jestのテストで使えるよう書き出し
module.exports = fn;
```

これをテストするには`done`という callback が必要となります。`done`がある場合 Jest はテストを終わらせずに非同期の処理を待ちます。

`index.test.js`

```javascript
const fn = require("./index.js");

test('3秒後に貰ってきた名前は"terry"です', (done) => {
  function callback(name) {
    expect(name).toBe("terry");
    done();
  }
  fn.getName(callback);
});
```

この callback パターンに`try&catch`も使えます。

`index.js`

```javascript
const fn = {
  // 3秒後にcallbackを実行するgetName
  fetchData: (callback) =>
    setTimeout(() => {
      try {
        // 成功時
      } catch (error) {
        throw new Error("サーバーエラー");
      }
    }, 3000),
};

// Jestのテストで使えるよう書き出し
module.exports = fn;
```

`index.test.js`

```javascript
const fn = require("./index.js");

test("サーバーエラーが発生しましたか？", (done) => {
  function callback() {
    try {
      // 成功時
      done();
    } catch (error) {
      done();
    }
  }
  fn.fetchData(callback);
});
```

テストしてみると`サーバーエラー`というメッセージが確認できます。

## Promise パターン

callback パターンの次は Promise を使うパターンです。

> Promise が callback より明確で簡潔なのでおすすめします。

数字を貰ってくる関数を作成します。

`index.js`

```javascript
const fn = {
  // 3秒後に数字を返す
  getNumber: () => {
    const number = 26;
    return new Promise((resolve, reject) => {
      setTimeout(() => resolve(number), 3000);
    });
  },
};

// Jestのテストで使えるよう書き出し
module.exports = fn;
```

`index.test.js`

```javascript
const fn = require("./index.js");

test("貰ってきた数字は26です", () => {
  return fn.getNumber().then((age) => expect(age).toBe(26));
});
```

`done`はもう必要ではありません。**ただテストするときに`return`しないといけません。**

上の文をもうちょっと簡潔に作成することができます

```javascript
// これは
test("貰ってきた数字は26です", () => {
  return fn.getNumber().then((age) => expect(age).toBe(26));
});

//これと一緒
test("貰ってきた数字は26です", () => {
  return expect(fn.getNumber()).resolves.toBe(26);
});
```

`reject`イベントの場合も check してみましょう。

`index.js`

```javascript
const fn = {
  // 3秒後にエラーを返す
  getNumber: () => {
    // const number = 26;
    return new Promise((resolve, reject) => {
      setTimeout(() => reject("エラー"), 3000);
    });
  },
};

// Jestのテストで使えるよう書き出し
module.exports = fn;
```

`index.test.js`

```javascript
const fn = require("./index.js");

test("エラーが発生しました？", () => {
  return expect(fn.getNumber()).rejects.toMatch("エラー");
});
```

> `reject`と throw new Error は異なるので isThrow(ErrorMsg)は使えません

## async - await パターン

最後は`async - await`を使用してテストを実施します。

`index.js`

```javascript
const fn = {
  // 3秒後に数字を返す
  getNumber: () => {
    const number = 26;
    return new Promise((resolve, reject) => {
      setTimeout(() => resolve(number), 3000);
    });
  },
};

// Jestのテストで使えるよう書き出し
module.exports = fn;
```

`index.test.js`

```javascript
const fn = require("./index.js");

test("貰ってきた数字は26です", async () => {
  const number = await fn.getNumber();
  expect(number).toBe(26);
});
```

`resolves`, `rejects`と共に`async - await`を使う方法もあります。
`index.test.js`

```javascript
const fn = require("./index.js");

test("貰ってきた数字は26です", async () => {
  await expect(fn.getNumber()).resolves.toBe(26);
});
```

> return を async - await に変えただけ。。。
